ERROR:root:get_media_id_by_tag
Traceback (most recent call last):
  File "/usr/local/lib/python3.5/dist-packages/urllib3/connectionpool.py", line 380, in _make_request
    httplib_response = conn.getresponse(buffering=True)
TypeError: getresponse() got an unexpected keyword argument 'buffering'

During handling of the above exception, another exception occurred:

Traceback (most recent call last):
  File "/home/sid/Documents/instabot/instabot/src/instabot.py", line 352, in get_media_id_by_tag
    r = self.s.get(url_tag)
  File "/usr/local/lib/python3.5/dist-packages/requests/sessions.py", line 521, in get
    return self.request('GET', url, **kwargs)
  File "/usr/local/lib/python3.5/dist-packages/requests/sessions.py", line 508, in request
    resp = self.send(prep, **send_kwargs)
  File "/usr/local/lib/python3.5/dist-packages/requests/sessions.py", line 618, in send
    r = adapter.send(request, **kwargs)
  File "/usr/local/lib/python3.5/dist-packages/requests/adapters.py", line 440, in send
    timeout=timeout
  File "/usr/local/lib/python3.5/dist-packages/urllib3/connectionpool.py", line 601, in urlopen
    chunked=chunked)
  File "/usr/local/lib/python3.5/dist-packages/urllib3/connectionpool.py", line 383, in _make_request
    httplib_response = conn.getresponse()
  File "/usr/lib/python3.5/http/client.py", line 1198, in getresponse
    response.begin()
  File "/usr/lib/python3.5/http/client.py", line 297, in begin
    version, status, reason = self._read_status()
  File "/usr/lib/python3.5/http/client.py", line 258, in _read_status
    line = str(self.fp.readline(_MAXLINE + 1), "iso-8859-1")
  File "/usr/lib/python3.5/socket.py", line 576, in readinto
    return self._sock.recv_into(b)
  File "/usr/lib/python3.5/ssl.py", line 937, in recv_into
    return self.read(nbytes, buffer)
  File "/usr/lib/python3.5/ssl.py", line 799, in read
    return self._sslobj.read(len, buffer)
  File "/usr/lib/python3.5/ssl.py", line 583, in read
    v = self._sslobj.read(len, buffer)
KeyboardInterrupt
